<?xml version="1.0" ?>
<sdf version="1.9">
  <model name='hydronaut'>
    <link name='base_link'>
      <inertial>
        <pose>0.00416 0 -0.0493 0 0 0</pose>
        <mass>21.4</mass>
        <inertia>
          <ixx>2.500</ixx><ixy>0</ixy><ixz>-0.0044</ixz>
          <iyy>2.527</iyy><iyz>0</iyz><izz>2.526</izz>
        </inertia>
      </inertial>
      <collision name='base_link_collision'>
        <pose>0 0 0 0 0 0</pose>
        <geometry><box><size>0.5 0.44 0.1</size></box></geometry>
      </collision>
      <visual name='base_link_visual'>
        <pose>0 0 0 0 0 0</pose>
        <geometry><mesh><scale>1 1 1</scale><uri>file:///home/habib/hydronaut_ws/src/hydronaut_description/meshes/base_link.STL</uri></mesh></geometry>
        <material><ambient>0.8 0.8 0.8 1</ambient><diffuse>0.8 0.8 0.8 1</diffuse></material>
      </visual>
      <sensor name='imu_sensor' type='imu'>
        <pose>0 0 0 3.141592653589793 0 0</pose>
        <always_on>true</always_on>
        <update_rate>1000</update_rate>
      </sensor>
    </link>

    <joint name='joint_fl' type='revolute'><pose relative_to='base_link'>0.191 0.178 -0.002 0 0 0</pose><parent>base_link</parent><child>thruster_fl</child><axis><xyz>0.707 -0.707 0</xyz></axis></joint>
    <link name='thruster_fl'><pose relative_to='joint_fl'>0 0 0 0 0 0</pose><inertial><mass>0.002</mass><inertia><ixx>0.001</ixx><iyy>0.001</iyy><izz>0.001</izz></inertia></inertial><visual name='v1'><geometry><mesh><uri>file:///home/habib/hydronaut_ws/src/hydronaut_description/meshes/link_FL.STL</uri></mesh></geometry><material><ambient>0.2 0.2 0.2 1</ambient></material></visual></link>

    <joint name='joint_fr' type='revolute'><pose relative_to='base_link'>0.19 -0.177 -0.002 0 0 0</pose><parent>base_link</parent><child>thruster_fr</child><axis><xyz>0.707 0.707 0</xyz></axis></joint>
    <link name='thruster_fr'><pose relative_to='joint_fr'>0 0 0 0 0 0</pose><inertial><mass>0.002</mass><inertia><ixx>0.001</ixx><iyy>0.001</iyy><izz>0.001</izz></inertia></inertial><visual name='v2'><geometry><mesh><uri>file:///home/habib/hydronaut_ws/src/hydronaut_description/meshes/Link_FR.STL</uri></mesh></geometry><material><ambient>0.2 0.2 0.2 1</ambient></material></visual></link>

    <joint name='joint_bl' type='revolute'><pose relative_to='base_link'>-0.203 0.166 -0.002 0 0 0</pose><parent>base_link</parent><child>thruster_bl</child><axis><xyz>0.707 0.707 0</xyz></axis></joint>
    <link name='thruster_bl'><pose relative_to='joint_bl'>0 0 0 0 0 0</pose><inertial><mass>0.002</mass><inertia><ixx>0.001</ixx><iyy>0.001</iyy><izz>0.001</izz></inertia></inertial><visual name='v3'><geometry><mesh><uri>file:///home/habib/hydronaut_ws/src/hydronaut_description/meshes/Link_BL.STL</uri></mesh></geometry><material><ambient>0.2 0.2 0.2 1</ambient></material></visual></link>

    <joint name='joint_br' type='revolute'><pose relative_to='base_link'>-0.204 -0.166 0 0 0 0</pose><parent>base_link</parent><child>thruster_br</child><axis><xyz>0.707 -0.707 0</xyz></axis></joint>
    <link name='thruster_br'><pose relative_to='joint_br'>0 0 0 0 0 0</pose><inertial><mass>0.002</mass><inertia><ixx>0.001</ixx><iyy>0.001</iyy><izz>0.001</izz></inertia></inertial><visual name='v4'><geometry><mesh><uri>file:///home/habib/hydronaut_ws/src/hydronaut_description/meshes/Link_BR.STL</uri></mesh></geometry><material><ambient>0.2 0.2 0.2 1</ambient></material></visual></link>

    <joint name='joint_cl' type='revolute'><pose relative_to='base_link'>-0.002 0.136 -0.011 0 0 0</pose><parent>base_link</parent><child>thruster_cl</child><axis><xyz>0 0 1</xyz></axis></joint>
    <link name='thruster_cl'><pose relative_to='joint_cl'>0 0 0 0 0 0</pose><inertial><mass>0.002</mass><inertia><ixx>0.001</ixx><iyy>0.001</iyy><izz>0.001</izz></inertia></inertial><visual name='v5'><geometry><mesh><uri>file:///home/habib/hydronaut_ws/src/hydronaut_description/meshes/Link_CL.STL</uri></mesh></geometry><material><ambient>0.2 0.2 0.2 1</ambient></material></visual></link>

    <joint name='joint_cr' type='revolute'><pose relative_to='base_link'>-0.003 -0.135 -0.01 0 0 0</pose><parent>base_link</parent><child>thruster_cr</child><axis><xyz>0 0 1</xyz></axis></joint>
    <link name='thruster_cr'><pose relative_to='joint_cr'>0 0 0 0 0 0</pose><inertial><mass>0.002</mass><inertia><ixx>0.001</ixx><iyy>0.001</iyy><izz>0.001</izz></inertia></inertial><visual name='v6'><geometry><mesh><uri>file:///home/habib/hydronaut_ws/src/hydronaut_description/meshes/link_CR.STL</uri></mesh></geometry><material><ambient>0.2 0.2 0.2 1</ambient></material></visual></link>

    <plugin name='gz::sim::systems::Thruster' filename='gz-sim-thruster-system'>
      <namespace>hydronaut</namespace><joint_name>joint_fl</joint_name>
      <thrust_coefficient>-0.02</thrust_coefficient><fluid_density>1000</fluid_density><propeller_diameter>0.1</propeller_diameter>
      <velocity_control>true</velocity_control><use_angvel_cmd>False</use_angvel_cmd>
    </plugin>
    <plugin name='gz::sim::systems::Thruster' filename='gz-sim-thruster-system'>
      <namespace>hydronaut</namespace><joint_name>joint_fr</joint_name>
      <thrust_coefficient>0.02</thrust_coefficient><fluid_density>1000</fluid_density><propeller_diameter>0.1</propeller_diameter>
      <velocity_control>true</velocity_control><use_angvel_cmd>False</use_angvel_cmd>
    </plugin>
    <plugin name='gz::sim::systems::Thruster' filename='gz-sim-thruster-system'>
      <namespace>hydronaut</namespace><joint_name>joint_bl</joint_name>
      <thrust_coefficient>0.02</thrust_coefficient><fluid_density>1000</fluid_density><propeller_diameter>0.1</propeller_diameter>
      <velocity_control>true</velocity_control><use_angvel_cmd>False</use_angvel_cmd>
    </plugin>
    <plugin name='gz::sim::systems::Thruster' filename='gz-sim-thruster-system'>
      <namespace>hydronaut</namespace><joint_name>joint_br</joint_name>
      <thrust_coefficient>-0.02</thrust_coefficient><fluid_density>1000</fluid_density><propeller_diameter>0.1</propeller_diameter>
      <velocity_control>true</velocity_control><use_angvel_cmd>False</use_angvel_cmd>
    </plugin>
    <plugin name='gz::sim::systems::Thruster' filename='gz-sim-thruster-system'>
      <namespace>hydronaut</namespace><joint_name>joint_cl</joint_name>
      <thrust_coefficient>-0.02</thrust_coefficient><fluid_density>1000</fluid_density><propeller_diameter>0.1</propeller_diameter>
      <velocity_control>true</velocity_control><use_angvel_cmd>False</use_angvel_cmd>
    </plugin>
    <plugin name='gz::sim::systems::Thruster' filename='gz-sim-thruster-system'>
      <namespace>hydronaut</namespace><joint_name>joint_cr</joint_name>
      <thrust_coefficient>0.02</thrust_coefficient><fluid_density>1000</fluid_density><propeller_diameter>0.1</propeller_diameter>
      <velocity_control>true</velocity_control><use_angvel_cmd>False</use_angvel_cmd>
    </plugin>

    <plugin name='gz::sim::systems::Hydrodynamics' filename='gz-sim-hydrodynamics-system'>
      <link_name>base_link</link_name>
      <xDotU>-10.0</xDotU><yDotV>-10.0</yDotV><zDotW>-10.0</zDotW>
      <kDotP>-1.0</kDotP><mDotQ>-1.0</mDotQ><nDotR>-1.0</nDotR>
      <xU>-50.0</xU><yV>-50.0</yV><zW>-50.0</zW>
      <kP>-10.0</kP><mQ>-10.0</mQ><nR>-20.0</nR>
    </plugin>
    
<plugin name="ArduPilotPlugin" filename="ArduPilotPlugin">
      <fdm_addr>127.0.0.1</fdm_addr>
      <fdm_port_in>9002</fdm_port_in>
      <lock_step>1</lock_step>
      <no_time_sync>1</no_time_sync>
      <modelXYZToAirplaneXForwardZDown>0 0 0 3.14159265 0 0</modelXYZToAirplaneXForwardZDown>
      <gazeboXYZToNED>0 0 0 3.14159265 0 1.57079632</gazeboXYZToNED>
      <imuName>imu_sensor</imuName>
      
      <control channel='0' servomax='1900' servomin='1100'><type>COMMAND</type><jointName>joint_fr</jointName><cmd_topic>/model/hydronaut/joint/joint_fr/cmd_thrust</cmd_topic><offset>-0.5</offset><multiplier>80</multiplier></control>
      <control channel='1' servomax='1900' servomin='1100'><type>COMMAND</type><jointName>joint_fl</jointName><cmd_topic>/model/hydronaut/joint/joint_fl/cmd_thrust</cmd_topic><offset>-0.5</offset><multiplier>80</multiplier></control>
      <control channel='2' servomax='1900' servomin='1100'><type>COMMAND</type><jointName>joint_br</jointName><cmd_topic>/model/hydronaut/joint/joint_br/cmd_thrust</cmd_topic><offset>-0.5</offset><multiplier>80</multiplier></control>
      <control channel='3' servomax='1900' servomin='1100'><type>COMMAND</type><jointName>joint_bl</jointName><cmd_topic>/model/hydronaut/joint/joint_bl/cmd_thrust</cmd_topic><offset>-0.5</offset><multiplier>80</multiplier></control>
      <control channel='4' servomax='1900' servomin='1100'><type>COMMAND</type><jointName>joint_cr</jointName><cmd_topic>/model/hydronaut/joint/joint_cr/cmd_thrust</cmd_topic><offset>-0.5</offset><multiplier>-80</multiplier></control>
      <control channel='5' servomax='1900' servomin='1100'><type>COMMAND</type><jointName>joint_cl</jointName><cmd_topic>/model/hydronaut/joint/joint_cl/cmd_thrust</cmd_topic><offset>-0.5</offset><multiplier>-80</multiplier></control>
    </plugin>
  </model>
</sdf>
