<?xml version="1.0" ?>
<!-- =================================================================================== -->
<!-- |    This document was autogenerated by xacro from loco.urdf.xacro                | -->
<!-- |    EDITING THIS FILE BY HAND IS NOT RECOMMENDED                                 | -->
<!-- =================================================================================== -->
<robot name="loco">
  <material name="Blue">
    <color rgba="0.79 0.82 0.93 1"/>
  </material>
  <material name="DarkGray">
    <color rgba="0.3 0.3 0.3 1"/>
  </material>
  <link name="base_link">
    <inertial>
      <mass value="21.3"/>
      <origin rpy="0 0 0" xyz="0 0 -0.05"/>
      <inertia ixx="2.5" ixy="0.0" ixz="0.0" iyy="2.5" iyz="0.0" izz="2.5"/>
    </inertial>
    <visual>
      <geometry>
        <mesh filename="package://loco_description/meshes/base_link.STL"/>
      </geometry>
      <material name="Blue"/>
    </visual>
    <collision name="main_hull">
      <origin rpy="0 0 0" xyz="0 0 0"/>
      <geometry>
        <box size="0.5 0.44 0.1"/>
      </geometry>
    </collision>
  </link>
  <gazebo reference="base_link">
    <sensor name="imu_sensor" type="imu">
      <always_on>1</always_on>
      <update_rate>100</update_rate>
      <visualize>true</visualize>
      <topic>imu</topic>
    </sensor>
  </gazebo>
  <joint name="camera_joint" type="fixed">
    <parent link="base_link"/>
    <child link="camera_link"/>
    <origin rpy="0 0.785 0" xyz="0.3 0 0"/>
  </joint>
  <link name="camera_link">
    <inertial>
      <mass value="0.3"/>
      <inertia ixx="0.0001" ixy="0" ixz="0" iyy="0.0001" iyz="0" izz="0.0001"/>
    </inertial>
    <visual>
      <geometry>
        <box size="0.05 0.05 0.05"/>
      </geometry>
      <material name="DarkGray"/>
    </visual>
  </link>
  <gazebo reference="camera_link">
    <sensor name="front_camera" type="camera">
      <update_rate>30.0</update_rate>
      <visualize>true</visualize>
      <topic>camera</topic>
      <camera>
        <horizontal_fov>1.396</horizontal_fov>
        <image>
          <width>640</width>
          <height>480</height>
          <format>R8G8B8</format>
        </image>
        <clip>
          <near>0.02</near>
          <far>300</far>
        </clip>
      </camera>
    </sensor>
  </gazebo>
  <link name="thruster_fl">
    <inertial>
      <mass value="0.1"/>
      <inertia ixx="0.001" ixy="0" ixz="0" iyy="0.001" iyz="0" izz="0.001"/>
    </inertial>
    <visual>
      <geometry>
        <mesh filename="package://loco_description/meshes/link_FL.STL"/>
      </geometry>
      <material name="DarkGray"/>
    </visual>
  </link>
  <joint name="joint_fl" type="continuous">
    <origin rpy="0 0 0" xyz="0.191 0.178 -0.002"/>
    <parent link="base_link"/>
    <child link="thruster_fl"/>
    <axis xyz="0.707 -0.707 0"/>
  </joint>
  <gazebo>
    <plugin filename="gz-sim-thruster-system" name="gz::sim::systems::Thruster">
      <joint_name>joint_fl</joint_name>
      <thrust_coefficient>0.05</thrust_coefficient>
      <fluid_density>1000</fluid_density>
      <propeller_diameter>0.1</propeller_diameter>
    </plugin>
  </gazebo>
  <link name="thruster_fr">
    <inertial>
      <mass value="0.1"/>
      <inertia ixx="0.001" ixy="0" ixz="0" iyy="0.001" iyz="0" izz="0.001"/>
    </inertial>
    <visual>
      <geometry>
        <mesh filename="package://loco_description/meshes/Link_FR.STL"/>
      </geometry>
      <material name="DarkGray"/>
    </visual>
  </link>
  <joint name="joint_fr" type="continuous">
    <origin rpy="0 0 0" xyz="0.19 -0.177 -0.002"/>
    <parent link="base_link"/>
    <child link="thruster_fr"/>
    <axis xyz="0.707 0.707 0"/>
  </joint>
  <gazebo>
    <plugin filename="gz-sim-thruster-system" name="gz::sim::systems::Thruster">
      <joint_name>joint_fr</joint_name>
      <thrust_coefficient>0.05</thrust_coefficient>
      <fluid_density>1000</fluid_density>
      <propeller_diameter>0.1</propeller_diameter>
    </plugin>
  </gazebo>
  <link name="thruster_bl">
    <inertial>
      <mass value="0.1"/>
      <inertia ixx="0.001" ixy="0" ixz="0" iyy="0.001" iyz="0" izz="0.001"/>
    </inertial>
    <visual>
      <geometry>
        <mesh filename="package://loco_description/meshes/Link_BL.STL"/>
      </geometry>
      <material name="DarkGray"/>
    </visual>
  </link>
  <joint name="joint_bl" type="continuous">
    <origin rpy="0 0 0" xyz="-0.203 0.166 -0.002"/>
    <parent link="base_link"/>
    <child link="thruster_bl"/>
    <axis xyz="0.707 0.707 0"/>
  </joint>
  <gazebo>
    <plugin filename="gz-sim-thruster-system" name="gz::sim::systems::Thruster">
      <joint_name>joint_bl</joint_name>
      <thrust_coefficient>0.05</thrust_coefficient>
      <fluid_density>1000</fluid_density>
      <propeller_diameter>0.1</propeller_diameter>
    </plugin>
  </gazebo>
  <link name="thruster_br">
    <inertial>
      <mass value="0.1"/>
      <inertia ixx="0.001" ixy="0" ixz="0" iyy="0.001" iyz="0" izz="0.001"/>
    </inertial>
    <visual>
      <geometry>
        <mesh filename="package://loco_description/meshes/Link_BR.STL"/>
      </geometry>
      <material name="DarkGray"/>
    </visual>
  </link>
  <joint name="joint_br" type="continuous">
    <origin rpy="0 0 0" xyz="-0.204 -0.166 0.0"/>
    <parent link="base_link"/>
    <child link="thruster_br"/>
    <axis xyz="0.707 -0.707 0"/>
  </joint>
  <gazebo>
    <plugin filename="gz-sim-thruster-system" name="gz::sim::systems::Thruster">
      <joint_name>joint_br</joint_name>
      <thrust_coefficient>0.05</thrust_coefficient>
      <fluid_density>1000</fluid_density>
      <propeller_diameter>0.1</propeller_diameter>
    </plugin>
  </gazebo>
  <link name="thruster_cl">
    <inertial>
      <mass value="0.1"/>
      <inertia ixx="0.001" ixy="0" ixz="0" iyy="0.001" iyz="0" izz="0.001"/>
    </inertial>
    <visual>
      <geometry>
        <mesh filename="package://loco_description/meshes/Link_CL.STL"/>
      </geometry>
      <material name="DarkGray"/>
    </visual>
  </link>
  <joint name="joint_cl" type="continuous">
    <origin rpy="0 0 0" xyz="-0.002 0.136 -0.011"/>
    <parent link="base_link"/>
    <child link="thruster_cl"/>
    <axis xyz="0 0 1"/>
  </joint>
  <gazebo>
    <plugin filename="gz-sim-thruster-system" name="gz::sim::systems::Thruster">
      <joint_name>joint_cl</joint_name>
      <thrust_coefficient>0.05</thrust_coefficient>
      <fluid_density>1000</fluid_density>
      <propeller_diameter>0.1</propeller_diameter>
    </plugin>
  </gazebo>
  <link name="thruster_cr">
    <inertial>
      <mass value="0.1"/>
      <inertia ixx="0.001" ixy="0" ixz="0" iyy="0.001" iyz="0" izz="0.001"/>
    </inertial>
    <visual>
      <geometry>
        <mesh filename="package://loco_description/meshes/link_CR.STL"/>
      </geometry>
      <material name="DarkGray"/>
    </visual>
  </link>
  <joint name="joint_cr" type="continuous">
    <origin rpy="0 0 0" xyz="-0.003 -0.135 -0.01"/>
    <parent link="base_link"/>
    <child link="thruster_cr"/>
    <axis xyz="0 0 1"/>
  </joint>
  <gazebo>
    <plugin filename="gz-sim-thruster-system" name="gz::sim::systems::Thruster">
      <joint_name>joint_cr</joint_name>
      <thrust_coefficient>0.05</thrust_coefficient>
      <fluid_density>1000</fluid_density>
      <propeller_diameter>0.1</propeller_diameter>
    </plugin>
  </gazebo>
  <gazebo>
    <plugin filename="gz-sim-hydrodynamics-system" name="gz::sim::systems::Hydrodynamics">
      <link_name>base_link</link_name>
      <xDotU>-10.0</xDotU>
      <yDotV>-10.0</yDotV>
      <zDotW>-10.0</zDotW>
      <kDotP>-1.0</kDotP>
      <mDotQ>-1.0</mDotQ>
      <nDotR>-1.0</nDotR>
      <xU>-50.0</xU>
      <yV>-50.0</yV>
      <zW>-50.0</zW>
      <kP>-10.0</kP>
      <mQ>-10.0</mQ>
      <nR>-20.0</nR>
    </plugin>
  </gazebo>
  <gazebo>
    <plugin filename="/home/habib/ardupilot_gazebo/build/libArduPilotPlugin.so" name="ArduPilotPlugin">
      <fdm_addr>127.0.0.1</fdm_addr>
      <fdm_port_in>9003</fdm_port_in>
      <fdm_port_out>9002</fdm_port_out>
      <no_time_sync>1</no_time_sync>
      <modelXYZToAirplaneXForwardZDown>0 0 0 3.141593 0 0</modelXYZToAirplaneXForwardZDown>
      <gazeboXYZToNED>0 0 0 3.141593 0 0</gazeboXYZToNED>
      <imuName>imu_sensor</imuName>
      <connectionTimeoutMaxCount>5</connectionTimeoutMaxCount>
      <control channel="0" servomax="1900" servomin="1100">
        <type>COMMAND</type>
        <jointName>joint_fr</jointName>
        <multiplier>1</multiplier>
      </control>
      <control channel="1" servomax="1900" servomin="1100">
        <type>COMMAND</type>
        <jointName>joint_fl</jointName>
        <multiplier>1</multiplier>
      </control>
      <control channel="2" servomax="1900" servomin="1100">
        <type>COMMAND</type>
        <jointName>joint_br</jointName>
        <multiplier>1</multiplier>
      </control>
      <control channel="3" servomax="1900" servomin="1100">
        <type>COMMAND</type>
        <jointName>joint_bl</jointName>
        <multiplier>1</multiplier>
      </control>
      <control channel="4" servomax="1900" servomin="1100">
        <type>COMMAND</type>
        <jointName>joint_cr</jointName>
        <multiplier>1</multiplier>
      </control>
      <control channel="5" servomax="1900" servomin="1100">
        <type>COMMAND</type>
        <jointName>joint_cl</jointName>
        <multiplier>1</multiplier>
      </control>
    </plugin>
  </gazebo>
</robot>
